2025-01-08 08:36:38,064 [ERROR] No error handlers are registered, logging exception.
Traceback (most recent call last):
  File "/Users/ScottFenstermaker 1/.local/share/virtualenvs/unzipbot-hyucSE2c/lib/python3.10/site-packages/telegram/ext/_application.py", line 1325, in process_update
    await coroutine
  File "/Users/ScottFenstermaker 1/.local/share/virtualenvs/unzipbot-hyucSE2c/lib/python3.10/site-packages/telegram/ext/_handlers/basehandler.py", line 158, in handle_update
    return await self.callback(update, context)
TypeError: object NoneType can't be used in 'await' expression
2025-01-08 08:44:00,712 [ERROR] No error handlers are registered, logging exception.
Traceback (most recent call last):
  File "/Users/ScottFenstermaker 1/.local/share/virtualenvs/unzipbot-hyucSE2c/lib/python3.10/site-packages/telegram/ext/_application.py", line 1289, in process_update
    check = handler.check_update(update)  # Should the handler handle this update?
  File "/Users/ScottFenstermaker 1/.local/share/virtualenvs/unzipbot-hyucSE2c/lib/python3.10/site-packages/telegram/ext/_handlers/messagehandler.py", line 99, in check_update
    return self.filters.check_update(update) or False
AttributeError: type object 'Document' has no attribute 'check_update'
2025-01-08 08:51:14,207 [ERROR] No error handlers are registered, logging exception.
Traceback (most recent call last):
  File "/Users/ScottFenstermaker 1/.local/share/virtualenvs/unzipbot-hyucSE2c/lib/python3.10/site-packages/telegram/ext/_application.py", line 1289, in process_update
    check = handler.check_update(update)  # Should the handler handle this update?
  File "/Users/ScottFenstermaker 1/.local/share/virtualenvs/unzipbot-hyucSE2c/lib/python3.10/site-packages/telegram/ext/_handlers/messagehandler.py", line 99, in check_update
    return self.filters.check_update(update) or False
AttributeError: type object 'Document' has no attribute 'check_update'
2025-01-08 08:53:35,969 [ERROR] No error handlers are registered, logging exception.
Traceback (most recent call last):
  File "/Users/ScottFenstermaker 1/.local/share/virtualenvs/unzipbot-hyucSE2c/lib/python3.10/site-packages/telegram/ext/_application.py", line 1289, in process_update
    check = handler.check_update(update)  # Should the handler handle this update?
  File "/Users/ScottFenstermaker 1/.local/share/virtualenvs/unzipbot-hyucSE2c/lib/python3.10/site-packages/telegram/ext/_handlers/messagehandler.py", line 99, in check_update
    return self.filters.check_update(update) or False
AttributeError: type object 'Document' has no attribute 'check_update'
2025-01-08 08:54:12,152 [ERROR] No error handlers are registered, logging exception.
Traceback (most recent call last):
  File "/Users/ScottFenstermaker 1/.local/share/virtualenvs/unzipbot-hyucSE2c/lib/python3.10/site-packages/telegram/ext/_application.py", line 1289, in process_update
    check = handler.check_update(update)  # Should the handler handle this update?
  File "/Users/ScottFenstermaker 1/.local/share/virtualenvs/unzipbot-hyucSE2c/lib/python3.10/site-packages/telegram/ext/_handlers/messagehandler.py", line 99, in check_update
    return self.filters.check_update(update) or False
AttributeError: type object 'Document' has no attribute 'check_update'
2025-01-08 08:56:35,771 [ERROR] No error handlers are registered, logging exception.
Traceback (most recent call last):
  File "/Users/ScottFenstermaker 1/.local/share/virtualenvs/unzipbot-hyucSE2c/lib/python3.10/site-packages/telegram/ext/_application.py", line 1325, in process_update
    await coroutine
  File "/Users/ScottFenstermaker 1/.local/share/virtualenvs/unzipbot-hyucSE2c/lib/python3.10/site-packages/telegram/ext/_handlers/basehandler.py", line 158, in handle_update
    return await self.callback(update, context)
  File "./unzipbot.py", line 69, in handle_file
    file.get_file().download(file_path)
AttributeError: 'coroutine' object has no attribute 'download'
2025-01-08 09:35:29,418 [ERROR] No error handlers are registered, logging exception.
Traceback (most recent call last):
  File "/Users/ScottFenstermaker 1/.local/share/virtualenvs/unzipbot-hyucSE2c/lib/python3.10/site-packages/telegram/ext/_application.py", line 1325, in process_update
    await coroutine
  File "/Users/ScottFenstermaker 1/.local/share/virtualenvs/unzipbot-hyucSE2c/lib/python3.10/site-packages/telegram/ext/_handlers/basehandler.py", line 158, in handle_update
    return await self.callback(update, context)
  File "./unzipbot.py", line 69, in handle_file
    await file.get_file().download(file_path)
AttributeError: 'coroutine' object has no attribute 'download'
2025-01-08 09:36:45,329 [ERROR] No error handlers are registered, logging exception.
Traceback (most recent call last):
  File "/Users/ScottFenstermaker 1/.local/share/virtualenvs/unzipbot-hyucSE2c/lib/python3.10/site-packages/telegram/ext/_application.py", line 1325, in process_update
    await coroutine
  File "/Users/ScottFenstermaker 1/.local/share/virtualenvs/unzipbot-hyucSE2c/lib/python3.10/site-packages/telegram/ext/_handlers/basehandler.py", line 158, in handle_update
    return await self.callback(update, context)
  File "./unzipbot.py", line 70, in handle_file
    file_obj.download(file_path)
AttributeError: 'File' object has no attribute 'download'
2025-01-08 09:40:25,492 [ERROR] No error handlers are registered, logging exception.
Traceback (most recent call last):
  File "/Users/ScottFenstermaker 1/.local/share/virtualenvs/unzipbot-hyucSE2c/lib/python3.10/site-packages/telegram/ext/_application.py", line 1325, in process_update
    await coroutine
  File "/Users/ScottFenstermaker 1/.local/share/virtualenvs/unzipbot-hyucSE2c/lib/python3.10/site-packages/telegram/ext/_handlers/basehandler.py", line 158, in handle_update
    return await self.callback(update, context)
  File "./unzipbot.py", line 102, in handle_file
    await update.message.reply_photo(photo=open(file_path, 'rb'))
  File "/Users/ScottFenstermaker 1/.local/share/virtualenvs/unzipbot-hyucSE2c/lib/python3.10/site-packages/telegram/_message.py", line 2185, in reply_photo
    return await self.get_bot().send_photo(
  File "/Users/ScottFenstermaker 1/.local/share/virtualenvs/unzipbot-hyucSE2c/lib/python3.10/site-packages/telegram/ext/_extbot.py", line 3017, in send_photo
    return await super().send_photo(
  File "/Users/ScottFenstermaker 1/.local/share/virtualenvs/unzipbot-hyucSE2c/lib/python3.10/site-packages/telegram/_bot.py", line 1397, in send_photo
    return await self._send_message(
  File "/Users/ScottFenstermaker 1/.local/share/virtualenvs/unzipbot-hyucSE2c/lib/python3.10/site-packages/telegram/ext/_extbot.py", line 610, in _send_message
    result = await super()._send_message(
  File "/Users/ScottFenstermaker 1/.local/share/virtualenvs/unzipbot-hyucSE2c/lib/python3.10/site-packages/telegram/_bot.py", line 731, in _send_message
    result = await self._post(
  File "/Users/ScottFenstermaker 1/.local/share/virtualenvs/unzipbot-hyucSE2c/lib/python3.10/site-packages/telegram/_bot.py", line 619, in _post
    return await self._do_post(
  File "/Users/ScottFenstermaker 1/.local/share/virtualenvs/unzipbot-hyucSE2c/lib/python3.10/site-packages/telegram/ext/_extbot.py", line 354, in _do_post
    return await super()._do_post(
  File "/Users/ScottFenstermaker 1/.local/share/virtualenvs/unzipbot-hyucSE2c/lib/python3.10/site-packages/telegram/_bot.py", line 648, in _do_post
    result = await request.post(
  File "/Users/ScottFenstermaker 1/.local/share/virtualenvs/unzipbot-hyucSE2c/lib/python3.10/site-packages/telegram/request/_baserequest.py", line 202, in post
    result = await self._request_wrapper(
  File "/Users/ScottFenstermaker 1/.local/share/virtualenvs/unzipbot-hyucSE2c/lib/python3.10/site-packages/telegram/request/_baserequest.py", line 383, in _request_wrapper
    raise BadRequest(message)
telegram.error.BadRequest: Image_process_failed
2025-01-08 09:50:32,768 [ERROR] An error occurred while sending the photo: Image_process_failed
2025-01-08 09:50:33,187 [ERROR] An error occurred while sending the photo: Image_process_failed
2025-01-08 09:50:33,506 [ERROR] An error occurred while sending the photo: Image_process_failed
2025-01-08 09:50:33,866 [ERROR] An error occurred while sending the photo: Image_process_failed
2025-01-08 09:50:34,321 [ERROR] An error occurred while sending the photo: Image_process_failed
2025-01-08 09:50:34,666 [ERROR] An error occurred while sending the photo: Image_process_failed
2025-01-08 09:50:35,013 [ERROR] An error occurred while sending the photo: Image_process_failed
2025-01-08 09:50:35,390 [ERROR] An error occurred while sending the photo: Image_process_failed
2025-01-08 09:50:35,766 [ERROR] An error occurred while sending the photo: Image_process_failed
2025-01-08 09:50:36,209 [ERROR] An error occurred while sending the photo: Image_process_failed
2025-01-08 09:50:36,650 [ERROR] An error occurred while sending the photo: Image_process_failed
2025-01-08 09:50:37,134 [ERROR] An error occurred while sending the photo: Image_process_failed
2025-01-08 09:50:38,142 [ERROR] An error occurred while sending the photo: Image_process_failed
2025-01-08 09:50:38,571 [ERROR] An error occurred while sending the photo: Image_process_failed
2025-01-08 09:50:39,107 [ERROR] An error occurred while sending the photo: Image_process_failed
2025-01-08 09:50:39,537 [ERROR] An error occurred while sending the photo: Image_process_failed
2025-01-08 09:50:39,897 [ERROR] An error occurred while sending the photo: Image_process_failed
2025-01-08 09:50:40,241 [ERROR] An error occurred while sending the photo: Image_process_failed
2025-01-08 09:50:40,860 [ERROR] An error occurred while sending the photo: Image_process_failed
2025-01-08 09:50:41,335 [ERROR] An error occurred while sending the photo: Image_process_failed
2025-01-08 09:50:46,342 [ERROR] No error handlers are registered, logging exception.
Traceback (most recent call last):
  File "/Users/ScottFenstermaker 1/.local/share/virtualenvs/unzipbot-hyucSE2c/lib/python3.10/site-packages/httpx/_transports/default.py", line 101, in map_httpcore_exceptions
    yield
  File "/Users/ScottFenstermaker 1/.local/share/virtualenvs/unzipbot-hyucSE2c/lib/python3.10/site-packages/httpx/_transports/default.py", line 394, in handle_async_request
    resp = await self._pool.handle_async_request(req)
  File "/Users/ScottFenstermaker 1/.local/share/virtualenvs/unzipbot-hyucSE2c/lib/python3.10/site-packages/httpcore/_async/connection_pool.py", line 256, in handle_async_request
    raise exc from None
  File "/Users/ScottFenstermaker 1/.local/share/virtualenvs/unzipbot-hyucSE2c/lib/python3.10/site-packages/httpcore/_async/connection_pool.py", line 236, in handle_async_request
    response = await connection.handle_async_request(
  File "/Users/ScottFenstermaker 1/.local/share/virtualenvs/unzipbot-hyucSE2c/lib/python3.10/site-packages/httpcore/_async/connection.py", line 103, in handle_async_request
    return await self._connection.handle_async_request(request)
  File "/Users/ScottFenstermaker 1/.local/share/virtualenvs/unzipbot-hyucSE2c/lib/python3.10/site-packages/httpcore/_async/http11.py", line 136, in handle_async_request
    raise exc
  File "/Users/ScottFenstermaker 1/.local/share/virtualenvs/unzipbot-hyucSE2c/lib/python3.10/site-packages/httpcore/_async/http11.py", line 106, in handle_async_request
    ) = await self._receive_response_headers(**kwargs)
  File "/usr/local/Cellar/python@3.10/3.10.12/Frameworks/Python.framework/Versions/3.10/lib/python3.10/contextlib.py", line 153, in __exit__
    self.gen.throw(typ, value, traceback)
  File "/Users/ScottFenstermaker 1/.local/share/virtualenvs/unzipbot-hyucSE2c/lib/python3.10/site-packages/httpcore/_exceptions.py", line 14, in map_exceptions
    raise to_exc(exc) from exc
httpcore.ReadTimeout

The above exception was the direct cause of the following exception:

Traceback (most recent call last):
  File "/Users/ScottFenstermaker 1/.local/share/virtualenvs/unzipbot-hyucSE2c/lib/python3.10/site-packages/telegram/request/_httpxrequest.py", line 293, in do_request
    res = await self._client.request(
  File "/Users/ScottFenstermaker 1/.local/share/virtualenvs/unzipbot-hyucSE2c/lib/python3.10/site-packages/httpx/_client.py", line 1540, in request
    return await self.send(request, auth=auth, follow_redirects=follow_redirects)
  File "/Users/ScottFenstermaker 1/.local/share/virtualenvs/unzipbot-hyucSE2c/lib/python3.10/site-packages/httpx/_client.py", line 1629, in send
    response = await self._send_handling_auth(
  File "/Users/ScottFenstermaker 1/.local/share/virtualenvs/unzipbot-hyucSE2c/lib/python3.10/site-packages/httpx/_client.py", line 1657, in _send_handling_auth
    response = await self._send_handling_redirects(
  File "/Users/ScottFenstermaker 1/.local/share/virtualenvs/unzipbot-hyucSE2c/lib/python3.10/site-packages/httpx/_client.py", line 1694, in _send_handling_redirects
    response = await self._send_single_request(request)
  File "/Users/ScottFenstermaker 1/.local/share/virtualenvs/unzipbot-hyucSE2c/lib/python3.10/site-packages/httpx/_client.py", line 1730, in _send_single_request
    response = await transport.handle_async_request(request)
  File "/Users/ScottFenstermaker 1/.local/share/virtualenvs/unzipbot-hyucSE2c/lib/python3.10/site-packages/httpx/_transports/default.py", line 393, in handle_async_request
    with map_httpcore_exceptions():
  File "/usr/local/Cellar/python@3.10/3.10.12/Frameworks/Python.framework/Versions/3.10/lib/python3.10/contextlib.py", line 153, in __exit__
    self.gen.throw(typ, value, traceback)
  File "/Users/ScottFenstermaker 1/.local/share/virtualenvs/unzipbot-hyucSE2c/lib/python3.10/site-packages/httpx/_transports/default.py", line 118, in map_httpcore_exceptions
    raise mapped_exc(message) from exc
httpx.ReadTimeout

The above exception was the direct cause of the following exception:

Traceback (most recent call last):
  File "/Users/ScottFenstermaker 1/.local/share/virtualenvs/unzipbot-hyucSE2c/lib/python3.10/site-packages/telegram/ext/_application.py", line 1325, in process_update
    await coroutine
  File "/Users/ScottFenstermaker 1/.local/share/virtualenvs/unzipbot-hyucSE2c/lib/python3.10/site-packages/telegram/ext/_handlers/basehandler.py", line 158, in handle_update
    return await self.callback(update, context)
  File "./unzipbot.py", line 107, in handle_file
    await update.message.reply_text("An error occurred while sending the photo.")
  File "/Users/ScottFenstermaker 1/.local/share/virtualenvs/unzipbot-hyucSE2c/lib/python3.10/site-packages/telegram/_message.py", line 1771, in reply_text
    return await self.get_bot().send_message(
  File "/Users/ScottFenstermaker 1/.local/share/virtualenvs/unzipbot-hyucSE2c/lib/python3.10/site-packages/telegram/ext/_extbot.py", line 2965, in send_message
    return await super().send_message(
  File "/Users/ScottFenstermaker 1/.local/share/virtualenvs/unzipbot-hyucSE2c/lib/python3.10/site-packages/telegram/_bot.py", line 1019, in send_message
    return await self._send_message(
  File "/Users/ScottFenstermaker 1/.local/share/virtualenvs/unzipbot-hyucSE2c/lib/python3.10/site-packages/telegram/ext/_extbot.py", line 610, in _send_message
    result = await super()._send_message(
  File "/Users/ScottFenstermaker 1/.local/share/virtualenvs/unzipbot-hyucSE2c/lib/python3.10/site-packages/telegram/_bot.py", line 731, in _send_message
    result = await self._post(
  File "/Users/ScottFenstermaker 1/.local/share/virtualenvs/unzipbot-hyucSE2c/lib/python3.10/site-packages/telegram/_bot.py", line 619, in _post
    return await self._do_post(
  File "/Users/ScottFenstermaker 1/.local/share/virtualenvs/unzipbot-hyucSE2c/lib/python3.10/site-packages/telegram/ext/_extbot.py", line 354, in _do_post
    return await super()._do_post(
  File "/Users/ScottFenstermaker 1/.local/share/virtualenvs/unzipbot-hyucSE2c/lib/python3.10/site-packages/telegram/_bot.py", line 648, in _do_post
    result = await request.post(
  File "/Users/ScottFenstermaker 1/.local/share/virtualenvs/unzipbot-hyucSE2c/lib/python3.10/site-packages/telegram/request/_baserequest.py", line 202, in post
    result = await self._request_wrapper(
  File "/Users/ScottFenstermaker 1/.local/share/virtualenvs/unzipbot-hyucSE2c/lib/python3.10/site-packages/telegram/request/_baserequest.py", line 334, in _request_wrapper
    code, payload = await self.do_request(
  File "/Users/ScottFenstermaker 1/.local/share/virtualenvs/unzipbot-hyucSE2c/lib/python3.10/site-packages/telegram/request/_httpxrequest.py", line 310, in do_request
    raise TimedOut from err
telegram.error.TimedOut: Timed out
2025-01-08 10:30:30,388 [ERROR] An error occurred while sending message: Message.reply_document() got an unexpected keyword argument 'timeout'
2025-01-08 10:30:30,391 [ERROR] No error handlers are registered, logging exception.
Traceback (most recent call last):
  File "/Users/ScottFenstermaker 1/.local/share/virtualenvs/unzipbot-hyucSE2c/lib/python3.10/site-packages/telegram/ext/_application.py", line 1325, in process_update
    await coroutine
  File "/Users/ScottFenstermaker 1/.local/share/virtualenvs/unzipbot-hyucSE2c/lib/python3.10/site-packages/telegram/ext/_handlers/basehandler.py", line 158, in handle_update
    return await self.callback(update, context)
  File "./unzipbot.py", line 119, in handle_file
    await send_with_retry(update.message.reply_document, document=open(file_path, 'rb'))
  File "./unzipbot.py", line 138, in send_with_retry
    await send_func(**kwargs, timeout=60)  # Increase timeout to 60 seconds
TypeError: Message.reply_document() got an unexpected keyword argument 'timeout'
2025-01-08 10:37:25,584 [ERROR] An error occurred while sending message: Image_process_failed
2025-01-08 11:42:31,576 [ERROR] An error occurred while sending message: File must be non-empty
2025-01-08 11:42:31,583 [ERROR] An error occurred while sending the document: File must be non-empty
2025-01-08 11:42:34,057 [ERROR] An error occurred while sending message: File must be non-empty
2025-01-08 11:42:34,059 [ERROR] An error occurred while sending the document: File must be non-empty
2025-01-08 11:44:32,565 [ERROR] An error occurred while sending message: File must be non-empty
2025-01-08 11:44:32,567 [ERROR] An error occurred while sending the document: File must be non-empty
2025-01-08 11:44:35,923 [ERROR] An error occurred while sending message: File must be non-empty
2025-01-08 11:44:35,924 [ERROR] An error occurred while sending the document: File must be non-empty
2025-01-08 11:47:42,303 [ERROR] An error occurred while sending message: File must be non-empty
2025-01-08 11:47:42,305 [ERROR] An error occurred while sending the document: File must be non-empty
2025-01-08 11:47:45,176 [ERROR] An error occurred while sending message: File must be non-empty
2025-01-08 11:47:45,181 [ERROR] An error occurred while sending the document: File must be non-empty
